[I 240429 15:09:58 angel_ui:90] Placing order for 10 shares of RELIANCE-EQ for account A55610949...
[I 240429 15:09:59 angel_ui:109] Order response: {'status': True, 'message': 'SUCCESS', 'errorcode': '', 'data': {'script': 'RELIANCE-EQ', 'orderid': '240429001511570', 'uniqueorderid': '6fd3e933-37f0-42ab-bd45-5eed8d39837b'}}
[I 240429 15:10:11 angel_ui:73] JSON data has not been updated.
[I 240429 15:10:11 angel_ui:20] Username: A55610949
[I 240429 15:10:11 angel_ui:21] Available Funds: 100.0
[I 240429 15:10:11 smartConnect:113] in pool
[I 240429 15:10:12 angel_ui:285] Thread for A55610949 has completed.
[E 240429 15:10:24 angel_ui:118] Error placing order for A55610949: HTTPSConnectionPool(host='apiconnect.angelbroking.com', port=443): Read timed out. (read timeout=7)
    Traceback (most recent call last):
      File "C:\Users\aarya\AppData\Local\Programs\Python\Python311\Lib\site-packages\urllib3\connectionpool.py", line 468, in _make_request
        self._validate_conn(conn)
      File "C:\Users\aarya\AppData\Local\Programs\Python\Python311\Lib\site-packages\urllib3\connectionpool.py", line 1097, in _validate_conn
        conn.connect()
      File "C:\Users\aarya\AppData\Local\Programs\Python\Python311\Lib\site-packages\urllib3\connection.py", line 642, in connect
        sock_and_verified = _ssl_wrap_socket_and_match_hostname(
                            ^^^^^^^^^^^^^^^^^^^^^^^^^^^^^^^^^^^^
      File "C:\Users\aarya\AppData\Local\Programs\Python\Python311\Lib\site-packages\urllib3\connection.py", line 783, in _ssl_wrap_socket_and_match_hostname
        ssl_sock = ssl_wrap_socket(
                   ^^^^^^^^^^^^^^^^
      File "C:\Users\aarya\AppData\Local\Programs\Python\Python311\Lib\site-packages\urllib3\util\ssl_.py", line 471, in ssl_wrap_socket
        ssl_sock = _ssl_wrap_socket_impl(sock, context, tls_in_tls, server_hostname)
                   ^^^^^^^^^^^^^^^^^^^^^^^^^^^^^^^^^^^^^^^^^^^^^^^^^^^^^^^^^^^^^^^^^
      File "C:\Users\aarya\AppData\Local\Programs\Python\Python311\Lib\site-packages\urllib3\util\ssl_.py", line 515, in _ssl_wrap_socket_impl
        return ssl_context.wrap_socket(sock, server_hostname=server_hostname)
               ^^^^^^^^^^^^^^^^^^^^^^^^^^^^^^^^^^^^^^^^^^^^^^^^^^^^^^^^^^^^^^
      File "C:\Users\aarya\AppData\Local\Programs\Python\Python311\Lib\ssl.py", line 517, in wrap_socket
        return self.sslsocket_class._create(
               ^^^^^^^^^^^^^^^^^^^^^^^^^^^^^
      File "C:\Users\aarya\AppData\Local\Programs\Python\Python311\Lib\ssl.py", line 1108, in _create
        self.do_handshake()
      File "C:\Users\aarya\AppData\Local\Programs\Python\Python311\Lib\ssl.py", line 1379, in do_handshake
        self._sslobj.do_handshake()
    TimeoutError: _ssl.c:989: The handshake operation timed out
    
    The above exception was the direct cause of the following exception:
    
    Traceback (most recent call last):
      File "C:\Users\aarya\AppData\Local\Programs\Python\Python311\Lib\site-packages\requests\adapters.py", line 486, in send
        resp = conn.urlopen(
               ^^^^^^^^^^^^^
      File "C:\Users\aarya\AppData\Local\Programs\Python\Python311\Lib\site-packages\urllib3\connectionpool.py", line 845, in urlopen
        retries = retries.increment(
                  ^^^^^^^^^^^^^^^^^^
      File "C:\Users\aarya\AppData\Local\Programs\Python\Python311\Lib\site-packages\urllib3\util\retry.py", line 470, in increment
        raise reraise(type(error), error, _stacktrace)
              ^^^^^^^^^^^^^^^^^^^^^^^^^^^^^^^^^^^^^^^^
      File "C:\Users\aarya\AppData\Local\Programs\Python\Python311\Lib\site-packages\urllib3\util\util.py", line 39, in reraise
        raise value
      File "C:\Users\aarya\AppData\Local\Programs\Python\Python311\Lib\site-packages\urllib3\connectionpool.py", line 791, in urlopen
        response = self._make_request(
                   ^^^^^^^^^^^^^^^^^^^
      File "C:\Users\aarya\AppData\Local\Programs\Python\Python311\Lib\site-packages\urllib3\connectionpool.py", line 492, in _make_request
        raise new_e
      File "C:\Users\aarya\AppData\Local\Programs\Python\Python311\Lib\site-packages\urllib3\connectionpool.py", line 470, in _make_request
        self._raise_timeout(err=e, url=url, timeout_value=conn.timeout)
      File "C:\Users\aarya\AppData\Local\Programs\Python\Python311\Lib\site-packages\urllib3\connectionpool.py", line 371, in _raise_timeout
        raise ReadTimeoutError(
    urllib3.exceptions.ReadTimeoutError: HTTPSConnectionPool(host='apiconnect.angelbroking.com', port=443): Read timed out. (read timeout=7)
    
    During handling of the above exception, another exception occurred:
    
    Traceback (most recent call last):
      File "c:\Users\aarya\Desktop\stocks\competetion\angel_ui.py", line 79, in place_order
        data = smartApi.generateSession(username, password, totp)
               ^^^^^^^^^^^^^^^^^^^^^^^^^^^^^^^^^^^^^^^^^^^^^^^^^^
      File "C:\Users\aarya\AppData\Roaming\Python\Python311\site-packages\SmartApi\smartConnect.py", line 267, in generateSession
        user = self.getProfile(refreshToken)
               ^^^^^^^^^^^^^^^^^^^^^^^^^^^^^
      File "C:\Users\aarya\AppData\Roaming\Python\Python311\site-packages\SmartApi\smartConnect.py", line 310, in getProfile
        user=self._getRequest("api.user.profile",{"refreshToken":refreshToken})
             ^^^^^^^^^^^^^^^^^^^^^^^^^^^^^^^^^^^^^^^^^^^^^^^^^^^^^^^^^^^^^^^^^^
      File "C:\Users\aarya\AppData\Roaming\Python\Python311\site-packages\SmartApi\smartConnect.py", line 253, in _getRequest
        return self._request(route, "GET", params)
               ^^^^^^^^^^^^^^^^^^^^^^^^^^^^^^^^^^^
      File "C:\Users\aarya\AppData\Roaming\Python\Python311\site-packages\SmartApi\smartConnect.py", line 210, in _request
        raise e
      File "C:\Users\aarya\AppData\Roaming\Python\Python311\site-packages\SmartApi\smartConnect.py", line 199, in _request
        r = requests.request(method,
            ^^^^^^^^^^^^^^^^^^^^^^^^
      File "C:\Users\aarya\AppData\Local\Programs\Python\Python311\Lib\site-packages\requests\api.py", line 59, in request
        return session.request(method=method, url=url, **kwargs)
               ^^^^^^^^^^^^^^^^^^^^^^^^^^^^^^^^^^^^^^^^^^^^^^^^^
      File "C:\Users\aarya\AppData\Local\Programs\Python\Python311\Lib\site-packages\requests\sessions.py", line 589, in request
        resp = self.send(prep, **send_kwargs)
               ^^^^^^^^^^^^^^^^^^^^^^^^^^^^^^
      File "C:\Users\aarya\AppData\Local\Programs\Python\Python311\Lib\site-packages\requests\sessions.py", line 703, in send
        r = adapter.send(request, **kwargs)
            ^^^^^^^^^^^^^^^^^^^^^^^^^^^^^^^
      File "C:\Users\aarya\AppData\Local\Programs\Python\Python311\Lib\site-packages\requests\adapters.py", line 532, in send
        raise ReadTimeout(e, request=request)
    requests.exceptions.ReadTimeout: HTTPSConnectionPool(host='apiconnect.angelbroking.com', port=443): Read timed out. (read timeout=7)
[I 240429 15:10:24 angel_ui:285] Thread for A55610949 has completed.
